[32m2022-11-04 12:09:26 -0700[0m - dagster - [34mDEBUG[0m - __ASSET_JOB - d5af6b26-e0d6-4b76-9f41-8a2b60941e44 - 1750287 - vis_raw_fetch_todb - LOGS_CAPTURED - Started capturing logs for step: vis_raw_fetch_todb.
[32m2022-11-04 12:09:26 -0700[0m - dagster - [34mDEBUG[0m - __ASSET_JOB - d5af6b26-e0d6-4b76-9f41-8a2b60941e44 - 1750287 - vis_raw_fetch_todb - STEP_START - Started execution of step "vis_raw_fetch_todb".
usage: __main__.py [-h] [--yamcsclient YAMCSCLIENT] [--outdir OUTDIR]
                   [--dburl DBURL]
__main__.py: error: unrecognized arguments: api grpc --lazy-load-user-code --socket /tmp/tmpupkzpdui --heartbeat --heartbeat-timeout 45 --fixed-server-id ebf6646c-f7a5-4049-b101-01d97a77d35b --log-level WARNING --package-name visdag
[32m2022-11-04 12:09:26 -0700[0m - dagster - [34mERROR[0m - [31m__ASSET_JOB - d5af6b26-e0d6-4b76-9f41-8a2b60941e44 - 1750287 - vis_raw_fetch_todb - STEP_FAILURE - Execution of step "vis_raw_fetch_todb" failed.

SystemExit: 2

Stack Trace:
  File "/Work/Anaconda/anaconda3_2022_Oct/envs/dagster/lib/python3.7/site-packages/dagster/_core/execution/plan/execute_plan.py", line 225, in dagster_event_sequence_for_step
    for step_event in check.generator(step_events):
  File "/Work/Anaconda/anaconda3_2022_Oct/envs/dagster/lib/python3.7/site-packages/dagster/_core/execution/plan/execute_step.py", line 361, in core_dagster_event_sequence_for_step
    _step_output_error_checked_user_event_sequence(step_context, user_event_sequence)
  File "/Work/Anaconda/anaconda3_2022_Oct/envs/dagster/lib/python3.7/site-packages/dagster/_core/execution/plan/execute_step.py", line 69, in _step_output_error_checked_user_event_sequence
    for user_event in user_event_sequence:
  File "/Work/Anaconda/anaconda3_2022_Oct/envs/dagster/lib/python3.7/site-packages/dagster/_core/execution/plan/compute.py", line 174, in execute_core_compute
    for step_output in _yield_compute_results(step_context, inputs, compute_fn):
  File "/Work/Anaconda/anaconda3_2022_Oct/envs/dagster/lib/python3.7/site-packages/dagster/_core/execution/plan/compute.py", line 151, in _yield_compute_results
    user_event_generator,
  File "/Work/Anaconda/anaconda3_2022_Oct/envs/dagster/lib/python3.7/site-packages/dagster/_utils/__init__.py", line 430, in iterate_with_context
    next_output = next(iterator)
  File "/Work/Anaconda/anaconda3_2022_Oct/envs/dagster/lib/python3.7/site-packages/dagster/_core/execution/plan/compute_generator.py", line 74, in _coerce_solid_compute_fn_to_iterator
    result = fn(context, **kwargs) if context_arg_provided else fn(**kwargs)
  File "/Work/VIPER/dagster/visdag/visdag/assets/vis_raw_fetch.py", line 48, in vis_raw_fetch_todb
    args = parser.parse_args()
  File "/Work/Anaconda/anaconda3_2022_Oct/envs/dagster/lib/python3.7/argparse.py", line 1758, in parse_args
    self.error(msg % ' '.join(argv))
  File "/Work/Anaconda/anaconda3_2022_Oct/envs/dagster/lib/python3.7/argparse.py", line 2508, in error
    self.exit(2, _('%(prog)s: error: %(message)s\n') % args)
  File "/Work/Anaconda/anaconda3_2022_Oct/envs/dagster/lib/python3.7/argparse.py", line 2495, in exit
    _sys.exit(status)
[0m
